Failure # 1 (occurred at 2020-02-04_14-53-43)
Traceback (most recent call last):
  File "/home/archie/anaconda3/envs/rl/lib/python3.7/site-packages/ray/tune/trial_runner.py", line 426, in _process_trial
    result = self.trial_executor.fetch_result(trial)
  File "/home/archie/anaconda3/envs/rl/lib/python3.7/site-packages/ray/tune/ray_trial_executor.py", line 378, in fetch_result
    result = ray.get(trial_future[0], DEFAULT_GET_TIMEOUT)
  File "/home/archie/anaconda3/envs/rl/lib/python3.7/site-packages/ray/worker.py", line 1457, in get
    raise value.as_instanceof_cause()
ray.exceptions.RayTaskError(ValueError): [36mray::MADDPG.__init__()[39m (pid=83281, ip=10.102.8.108)
  File "/home/archie/anaconda3/envs/rl/lib/python3.7/site-packages/tensorflow_core/python/framework/ops.py", line 1607, in _create_c_op
    c_op = c_api.TF_FinishOperation(op_desc)
tensorflow.python.framework.errors_impl.InvalidArgumentError: Shape must be rank 3 but is rank 2 for 'policy_0/critic/concat' (op: 'ConcatV2') with input shapes: [?,6,64], [?,6,64], [?,6,64], [?,6,64], [?,8], [?,8], [?,8], [?,8], [].

During handling of the above exception, another exception occurred:

[36mray::MADDPG.__init__()[39m (pid=83281, ip=10.102.8.108)
  File "python/ray/_raylet.pyx", line 626, in ray._raylet.execute_task
  File "python/ray/_raylet.pyx", line 633, in ray._raylet.execute_task
  File "python/ray/_raylet.pyx", line 634, in ray._raylet.execute_task
  File "python/ray/_raylet.pyx", line 636, in ray._raylet.execute_task
  File "python/ray/_raylet.pyx", line 619, in ray._raylet.execute_task.function_executor
  File "/home/archie/anaconda3/envs/rl/lib/python3.7/site-packages/ray/rllib/agents/trainer_template.py", line 90, in __init__
    Trainer.__init__(self, config, env, logger_creator)
  File "/home/archie/anaconda3/envs/rl/lib/python3.7/site-packages/ray/rllib/agents/trainer.py", line 398, in __init__
    Trainable.__init__(self, config, logger_creator)
  File "/home/archie/anaconda3/envs/rl/lib/python3.7/site-packages/ray/tune/trainable.py", line 96, in __init__
    self._setup(copy.deepcopy(self.config))
  File "/home/archie/anaconda3/envs/rl/lib/python3.7/site-packages/ray/rllib/agents/trainer.py", line 523, in _setup
    self._init(self.config, self.env_creator)
  File "/home/archie/anaconda3/envs/rl/lib/python3.7/site-packages/ray/rllib/agents/trainer_template.py", line 109, in _init
    self.config["num_workers"])
  File "/home/archie/anaconda3/envs/rl/lib/python3.7/site-packages/ray/rllib/agents/trainer.py", line 568, in _make_workers
    logdir=self.logdir)
  File "/home/archie/anaconda3/envs/rl/lib/python3.7/site-packages/ray/rllib/evaluation/worker_set.py", line 64, in __init__
    RolloutWorker, env_creator, policy, 0, self._local_config)
  File "/home/archie/anaconda3/envs/rl/lib/python3.7/site-packages/ray/rllib/evaluation/worker_set.py", line 220, in _make_worker
    _fake_sampler=config.get("_fake_sampler", False))
  File "/home/archie/anaconda3/envs/rl/lib/python3.7/site-packages/ray/rllib/evaluation/rollout_worker.py", line 350, in __init__
    self._build_policy_map(policy_dict, policy_config)
  File "/home/archie/anaconda3/envs/rl/lib/python3.7/site-packages/ray/rllib/evaluation/rollout_worker.py", line 766, in _build_policy_map
    policy_map[name] = cls(obs_space, act_space, merged_conf)
  File "/home/archie/anaconda3/envs/rl/lib/python3.7/site-packages/ray/rllib/contrib/maddpg/maddpg_policy.py", line 129, in __init__
    scope="critic")
  File "/home/archie/anaconda3/envs/rl/lib/python3.7/site-packages/ray/rllib/contrib/maddpg/maddpg_policy.py", line 337, in _build_critic_network
    out = tf.concat(obs_n + act_n, axis=1)
  File "/home/archie/anaconda3/envs/rl/lib/python3.7/site-packages/tensorflow_core/python/util/dispatch.py", line 180, in wrapper
    return target(*args, **kwargs)
  File "/home/archie/anaconda3/envs/rl/lib/python3.7/site-packages/tensorflow_core/python/ops/array_ops.py", line 1420, in concat
    return gen_array_ops.concat_v2(values=values, axis=axis, name=name)
  File "/home/archie/anaconda3/envs/rl/lib/python3.7/site-packages/tensorflow_core/python/ops/gen_array_ops.py", line 1257, in concat_v2
    "ConcatV2", values=values, axis=axis, name=name)
  File "/home/archie/anaconda3/envs/rl/lib/python3.7/site-packages/tensorflow_core/python/framework/op_def_library.py", line 794, in _apply_op_helper
    op_def=op_def)
  File "/home/archie/anaconda3/envs/rl/lib/python3.7/site-packages/tensorflow_core/python/util/deprecation.py", line 507, in new_func
    return func(*args, **kwargs)
  File "/home/archie/anaconda3/envs/rl/lib/python3.7/site-packages/tensorflow_core/python/framework/ops.py", line 3357, in create_op
    attrs, op_def, compute_device)
  File "/home/archie/anaconda3/envs/rl/lib/python3.7/site-packages/tensorflow_core/python/framework/ops.py", line 3426, in _create_op_internal
    op_def=op_def)
  File "/home/archie/anaconda3/envs/rl/lib/python3.7/site-packages/tensorflow_core/python/framework/ops.py", line 1770, in __init__
    control_input_ops)
  File "/home/archie/anaconda3/envs/rl/lib/python3.7/site-packages/tensorflow_core/python/framework/ops.py", line 1610, in _create_c_op
    raise ValueError(str(e))
ValueError: Shape must be rank 3 but is rank 2 for 'policy_0/critic/concat' (op: 'ConcatV2') with input shapes: [?,6,64], [?,6,64], [?,6,64], [?,6,64], [?,8], [?,8], [?,8], [?,8], [].

