Failure # 1 (occurred at 2020-02-04_15-54-35)
Traceback (most recent call last):
  File "/home/archie/anaconda3/envs/rl/lib/python3.7/site-packages/ray/tune/trial_runner.py", line 426, in _process_trial
    result = self.trial_executor.fetch_result(trial)
  File "/home/archie/anaconda3/envs/rl/lib/python3.7/site-packages/ray/tune/ray_trial_executor.py", line 378, in fetch_result
    result = ray.get(trial_future[0], DEFAULT_GET_TIMEOUT)
  File "/home/archie/anaconda3/envs/rl/lib/python3.7/site-packages/ray/worker.py", line 1457, in get
    raise value.as_instanceof_cause()
ray.exceptions.RayTaskError(AttributeError): [36mray::MADDPG.__init__()[39m (pid=91223, ip=10.102.8.108)
  File "python/ray/_raylet.pyx", line 626, in ray._raylet.execute_task
  File "python/ray/_raylet.pyx", line 633, in ray._raylet.execute_task
  File "python/ray/_raylet.pyx", line 634, in ray._raylet.execute_task
  File "python/ray/_raylet.pyx", line 636, in ray._raylet.execute_task
  File "python/ray/_raylet.pyx", line 619, in ray._raylet.execute_task.function_executor
  File "/home/archie/anaconda3/envs/rl/lib/python3.7/site-packages/ray/rllib/agents/trainer_template.py", line 90, in __init__
    Trainer.__init__(self, config, env, logger_creator)
  File "/home/archie/anaconda3/envs/rl/lib/python3.7/site-packages/ray/rllib/agents/trainer.py", line 398, in __init__
    Trainable.__init__(self, config, logger_creator)
  File "/home/archie/anaconda3/envs/rl/lib/python3.7/site-packages/ray/tune/trainable.py", line 96, in __init__
    self._setup(copy.deepcopy(self.config))
  File "/home/archie/anaconda3/envs/rl/lib/python3.7/site-packages/ray/rllib/agents/trainer.py", line 523, in _setup
    self._init(self.config, self.env_creator)
  File "/home/archie/anaconda3/envs/rl/lib/python3.7/site-packages/ray/rllib/agents/trainer_template.py", line 109, in _init
    self.config["num_workers"])
  File "/home/archie/anaconda3/envs/rl/lib/python3.7/site-packages/ray/rllib/agents/trainer.py", line 568, in _make_workers
    logdir=self.logdir)
  File "/home/archie/anaconda3/envs/rl/lib/python3.7/site-packages/ray/rllib/evaluation/worker_set.py", line 64, in __init__
    RolloutWorker, env_creator, policy, 0, self._local_config)
  File "/home/archie/anaconda3/envs/rl/lib/python3.7/site-packages/ray/rllib/evaluation/worker_set.py", line 220, in _make_worker
    _fake_sampler=config.get("_fake_sampler", False))
  File "/home/archie/anaconda3/envs/rl/lib/python3.7/site-packages/ray/rllib/evaluation/rollout_worker.py", line 350, in __init__
    self._build_policy_map(policy_dict, policy_config)
  File "/home/archie/anaconda3/envs/rl/lib/python3.7/site-packages/ray/rllib/evaluation/rollout_worker.py", line 766, in _build_policy_map
    policy_map[name] = cls(obs_space, act_space, merged_conf)
  File "/home/archie/anaconda3/envs/rl/lib/python3.7/site-packages/ray/rllib/contrib/maddpg/maddpg_policy.py", line 158, in __init__
    scope="actor"))
  File "/home/archie/anaconda3/envs/rl/lib/python3.7/site-packages/ray/rllib/contrib/maddpg/maddpg_policy.py", line 368, in _build_actor_network
    sampler = tfp.distributions.RelaxedOneHotCategorical(
AttributeError: 'NoneType' object has no attribute 'distributions'

